<?xml version="1.0" encoding="utf-8"?>
<!-- This URDF was automatically created by SolidWorks to URDF Exporter! Originally created by Stephen Brawner (brawner@gmail.com) 
     Commit Version: 1.6.0-4-g7f85cfe  Build Version: 1.6.7995.38578
     For more information, please see http://wiki.ros.org/sw_urdf_exporter -->
<robot
  name="ur5"
  xmlns:xacro="http://www.ros.org/wiki/xacro">

  <xacro:property name="M_PI" value="3.1415926536"/>

  <link name="base_footprint"/>
  <joint name="joint_0" type="fixed">
    <origin xyz="0 0 0.0532" rpy="0 0 0" />
    <parent link="base_footprint" />
    <child link="base_link" />
  </joint>

  <link
    name="base_link">
    <inertial>
      <origin
        xyz="0.0235759066632154 -4.024260750256E-07 -0.00267484602059103"
        rpy="0 0 0" />
      <mass
        value="1.7590663588329" />
      <inertia
        ixx="0.0111044047546135"
        ixy="-2.43496975298582E-06"
        ixz="3.4899177892921E-07"
        iyy="0.019324958776445"
        iyz="5.4412544869659E-08"
        izz="0.0303647859152603" />
    </inertial>
    <visual>
      <origin
        xyz="0 0 0"
        rpy="0 0 0" />
      <geometry>
        <mesh
          filename="package://ur5/meshes/base_link.STL" />
      </geometry>
      <material
        name="">
        <color
          rgba="0.752941176470588 0.752941176470588 0.752941176470588 1" />
      </material>
    </visual>
    <collision>
      <origin
        xyz="0 0 0"
        rpy="0 0 0" />
      <geometry>
        <mesh
          filename="package://ur5/meshes/base_link.STL" />
      </geometry>
    </collision>
  </link>

  <link
    name="Link1">
    <inertial>
      <origin
        xyz="-4.33139494392822E-06 -0.00186927605738119 0.00924020497630284"
        rpy="0 0 0" />
      <mass
        value="0.00001" />
      <inertia
        ixx="0.0028146857132453"
        ixy="-2.04222958000101E-08"
        ixz="-3.74832962999915E-08"
        iyy="0.00301831638792784"
        iyz="-0.000413432771678958"
        izz="0.00258081118256846" />
    </inertial>
    <visual>
      <origin
        xyz="0 0 0"
        rpy="0 0 0" />
      <geometry>
        <mesh
          filename="package://ur5/meshes/Link1.STL" />
      </geometry>
      <material
        name="">
        <color
          rgba="0.752941176470588 0.752941176470588 0.752941176470588 1" />
      </material>
    </visual>
    <collision>
      <origin
        xyz="0 0 0"
        rpy="0 0 0" />
      <geometry>
        <mesh
          filename="package://ur5/meshes/Link1.STL" />
      </geometry>
    </collision>
  </link>
  <joint
    name="Joint1"
    type="continuous">
    <origin
      xyz="0 0 0.0892"
      rpy="1.5708 0 0" />
    <parent
      link="base_link" />
    <child
      link="Link1" />
    <axis
      xyz="0 1 0" />
    <limit
      lower="-3.14"
      upper="3.14"
      effort="1000"
      velocity="1000" />
  </joint>

  <link
    name="Link2">
    <inertial>
      <origin
        xyz="-0.212499982180631 1.76727700529344E-09 0.134621416221834"
        rpy="0 0 0" />
      <mass
        value="0.00001" />
      <inertia
        ixx="0.00808994025531996"
        ixy="-7.71587058034231E-08"
        ixz="5.77898419873088E-10"
        iyy="0.0229057488132269"
        iyz="-3.96344123140802E-10"
        izz="0.0233130078218392" />
    </inertial>
    <visual>
      <origin
        xyz="0 0 0"
        rpy="0 0 0" />
      <geometry>
        <mesh
          filename="package://ur5/meshes/Link2.STL" />
      </geometry>
      <material
        name="">
        <color
          rgba="0.752941176470588 0.752941176470588 0.752941176470588 1" />
      </material>
    </visual>
    <collision>
      <origin
        xyz="0 0 0"
        rpy="0 0 0" />
      <geometry>
        <mesh
          filename="package://ur5/meshes/Link2.STL" />
      </geometry>
    </collision>
  </link>
  <joint
    name="Joint2"
    type="continuous">
    <origin
      xyz="0 0 0"
      rpy="0 0 0" />
    <parent
      link="Link1" />
    <child
      link="Link2" />
    <axis
      xyz="0 0 1" />
    <limit
      lower="-3.14"
      upper="3.14"
      effort="1000"
      velocity="1000" />
  </joint>

  <link
    name="Link3">
    <inertial>
      <origin
        xyz="-0.184404791090397 -5.75500430366471E-07 0.00441010722354379"
        rpy="0 0 0" />
      <mass
        value="0.00001" />
      <inertia
        ixx="0.00217649268314962"
        ixy="3.15920384836248E-08"
        ixz="-0.000151962208976148"
        iyy="0.00958565883046658"
        iyz="2.70874067564241E-08"
        izz="0.00967973060442219" />
    </inertial>
    <visual>
      <origin
        xyz="0 0 0"
        rpy="0 0 0" />
      <geometry>
        <mesh
          filename="package://ur5/meshes/Link3.STL" />
      </geometry>
      <material
        name="">
        <color
          rgba="0.752941176470588 0.752941176470588 0.752941176470588 1" />
      </material>
    </visual>
    <collision>
      <origin
        xyz="0 0 0"
        rpy="0 0 0" />
      <geometry>
        <mesh
          filename="package://ur5/meshes/Link3.STL" />
      </geometry>
    </collision>
  </link>
  <joint
    name="Joint3"
    type="continuous">
    <origin
      xyz="-0.425000000000001 0 0.0159999999999997"
      rpy="0 0 0" />
    <parent
      link="Link2" />
    <child
      link="Link3" />
    <axis
      xyz="0 0 -1" />
    <limit
      lower="-3.14"
      upper="3.14"
      effort="1000"
      velocity="1000" />
  </joint>

  <link
    name="Link4">
    <inertial>
      <origin
        xyz="1.47659840743497E-06 -0.0045599294197019 -0.00356635134023785"
        rpy="0 0 0" />
      <mass
        value="0.00001" />
      <inertia
        ixx="0.000402129033003172"
        ixy="1.5427603534118E-09"
        ixz="7.23887278008737E-09"
        iyy="0.000372758812319602"
        iyz="-5.68882815507802E-05"
        izz="0.000409988353950142" />
    </inertial>
    <visual>
      <origin
        xyz="0 0 0"
        rpy="0 0 0" />
      <geometry>
        <mesh
          filename="package://ur5/meshes/Link4.STL" />
      </geometry>
      <material
        name="">
        <color
          rgba="0.752941176470588 0.752941176470588 0.752941176470588 1" />
      </material>
    </visual>
    <collision>
      <origin
        xyz="0 0 0"
        rpy="0 0 0" />
      <geometry>
        <mesh
          filename="package://ur5/meshes/Link4.STL" />
      </geometry>
    </collision>
  </link>
  <joint
    name="Joint4"
    type="continuous">
    <origin
      xyz="-0.392429999999999 0 0.0929999999999997"
      rpy="1.5707963267949 0 0" />
    <parent
      link="Link3" />
    <child
      link="Link4" />
    <axis
      xyz="0 1 0" />
    <limit
      lower="-3.14"
      upper="3.14"
      effort="1000"
      velocity="1000" />
  </joint>

  <link
    name="Link5">
    <inertial>
      <origin
        xyz="-1.47659840832315E-06 0.00455992941970204 -0.00356635134023789"
        rpy="0 0 0" />
      <mass
        value="0.00001" />
      <inertia
        ixx="0.000402129080759367"
        ixy="1.54610002746828E-09"
        ixz="-7.23354782817657E-09"
        iyy="0.000372758849638208"
        iyz="5.68882591960725E-05"
        izz="0.000409988374505139" />
    </inertial>
    <visual>
      <origin
        xyz="0 0 0"
        rpy="0 0 0" />
      <geometry>
        <mesh
          filename="package://ur5/meshes/Link5.STL" />
      </geometry>
      <material
        name="">
        <color
          rgba="0.752941176470588 0.752941176470588 0.752941176470588 1" />
      </material>
    </visual>
    <collision>
      <origin
        xyz="0 0 0"
        rpy="0 0 0" />
      <geometry>
        <mesh
          filename="package://ur5/meshes/Link5.STL" />
      </geometry>
    </collision>
  </link>
  <joint
    name="Joint5"
    type="continuous">
    <origin
      xyz="0 0 0.0930000000000001"
      rpy="-1.5707963267949 0 0" />
    <parent
      link="Link4" />
    <child
      link="Link5" />
    <axis
      xyz="0 1 0" />
    <limit
      lower="-3.14"
      upper="3.14"
      effort="1000"
      velocity="1000" />
  </joint>

  <link
    name="Link6">
    <inertial>
      <origin
        xyz="2.60811271168837E-05 -4.07713123062102E-05 0.00134956082673351"
        rpy="0 0 0" />
      <mass
        value="0.00001" />
      <inertia
        ixx="0.000269803894778329"
        ixy="-7.00926865492166E-08"
        ixz="6.17721994428448E-07"
        iyy="0.000296833277877122"
        iyz="-4.20222681335834E-08"
        izz="0.000321580918794378" />
    </inertial>
    <visual>
      <origin
        xyz="0 0 0"
        rpy="0 0 0" />
      <geometry>
        <mesh
          filename="package://ur5/meshes/Link6.STL" />
      </geometry>
      <material
        name="">
        <color
          rgba="0.752941176470588 0.752941176470588 0.752941176470588 1" />
      </material>
    </visual>
    <collision>
      <origin
        xyz="0 0 0"
        rpy="0 0 0" />
      <geometry>
        <mesh
          filename="package://ur5/meshes/Link6.STL" />
      </geometry>
    </collision>
  </link>
  <joint
    name="Joint6"
    type="continuous">
    <origin
      xyz="0 0 0.1315"
      rpy="0 0 0" />
    <parent
      link="Link5" />
    <child
      link="Link6" />
    <axis
      xyz="0 0 1" />
    <limit
      lower="-3.14"
      upper="3.14"
      effort="1000"
      velocity="1000" />
  </joint>
 <!-- Transmissions for ROS Control -->

 <xacro:macro name="transmission_block" params="joint_name">
    <transmission name="tran1">
      <type>transmission_interface/SimpleTransmission</type>
      <joint name="${joint_name}">
      <hardwareInterface>hardware_interface/PositionJointInterface</hardwareInterface>
      </joint>
      <actuator name="motor1">
      <hardwareInterface>hardware_interface/PositionJointInterface</hardwareInterface>
      <mechanicalReduction>1</mechanicalReduction>
      </actuator>
    </transmission>
</xacro:macro>

<xacro:transmission_block joint_name="Joint1"/>
<xacro:transmission_block joint_name="Joint2"/>
<xacro:transmission_block joint_name="Joint3"/>
<xacro:transmission_block joint_name="Joint4"/>
<xacro:transmission_block joint_name="Joint5"/>
<xacro:transmission_block joint_name="Joint6"/>

<!-- ros_control plugin -->
<gazebo>
  <plugin name="gazebo_ros_control" filename="libgazebo_ros_control.so">
    <robotNamespace>/ur5</robotNamespace>
    <robotSimType>gazebo_ros_control/DefaultRobotHWSim</robotSimType>
    <legacyModeNS>true</legacyModeNS>
  </plugin>
</gazebo>

</robot>